Workbook

Sheet Operating Budgets
C1: Sales Budget
C2: 45985 | D2: 46015 | E2: 45682 | F2: 45713 | G2: 45741 | H2: 45772 | I2: 45802 | J2: 45833 | K2: 45863 | L2: 45894 | M2: 45925 | N2: 45955 | O2: 45986 | P2: 46016 | Q2: Jan | R2: Feb | S2: Total 2025
B3: Expected unit sales | C3: =C9 -> 8800 | D3: =D9 -> 9720 | E3: =E9 -> 10540 | F3: =F9 -> 14280 | G3: =G9 -> 22200 | H3: =H9 -> 24900 | I3: =I9 -> 29280 | J3: =J9 -> 37260 | ... Q3: =Q9 -> 11400 | S3: =SUM(E3:P3) -> 263080
B4: Unit selling price | C4: 409 | D4: 409 | E4: 409 | F4: 409 | G4: 409 | H4: 409 | I4: 409 | J4: 409 | K4: 409 | L4: 409 | M4: =M5/M3 -> 360 | N4: 409 | O4: 409 | P4: 409 | Q4: 409 | S4: =SUM(E4:P4) -> 4859
B5: Total sales | C5: =C4*C3 -> 3599200 | D5: =D4*D3 -> 3975480 | E5: =E4*E3 -> 4310860 | F5: =F4*F3 -> 5840520 | G5: =G4*G3 -> 9079800 | H5: =H4*H3 -> 10184100 | I5: =I4*I3 -> 11975520 | J5: =J4*J3 -> 15239340 | ... L5: =L4*L3 -> 9603320 | M5: 14040000 | N5: =N4*N3 -> 6535820 | O5: =O4*O3 -> 4122720 | P5: =P4*P3 -> 4024560 | Q5: =Q4*Q3 -> 4662600 | S5: =SUM(E5:P5) -> 105688720
K6: sales discount | L6: =-(M4/409-1) -> 0.1198044
C7: Production Budget
C8: 45985 | D8: 46015 | E8: 45682 | F8: 45713 | G8: 45741 | H8: 45772 | I8: 45802 | J8: 45833 | K8: 45863 | L8: 45894 | M8: 45925 | N8: 45955 | O8: 45986 | P8: 46016 | Q8: Jan | R8: Feb
B9: Expected unit sales (from Sales Budget) | C9: =C11-C10 -> 8800 | D9: =D11-D10 -> 9720 | E9: =E11-E10 -> 10540 | F9: =F11-F10 -> 14280 | G9: =G11-G10 -> 22200 | H9: =H11-H10 -> 24900 | I9: =I11-I10 -> 29280 | J9: =J11-J10 -> 37260 | ... Q9: =Q11-Q10 -> 11400 | S9: =SUM(E9:P9) -> 263080
B10: ADD: Ending finished goods units | C10: =D13*0.2 -> 2000 | D10: =E13*0.2 -> 2280 | E10: =F13*0.2 -> 3140 | F10: =G13*0.2 -> 4560 | G10: =H13*0.2 -> 5160 | H10: =I13*0.2 -> 6060 | I10: =J13*0.2 -> 7080 | J10: =K13*0.2 -> 5220 | ... Q10: =R13*0.2 -> 3000 | S10: =P10 -> 2400
B11: Total required units | C11: =SUM(C13+C12) -> 10800 | D11: =SUM(D13+D12) -> 12000 | E11: =SUM(E13+E12) -> 13680 | F11: =SUM(F13+F12) -> 18840 | G11: =SUM(G13+G12) -> 27360 | H11: =SUM(H13+H12) -> 30960 | I11: =SUM(I13+I12) -> 36360 | J11: =SUM(J13+J12) -> 42480 | ... R11: =SUM(R13+R12) -> 18000 | S11: =S9+S10 -> 265480
B12: LESS: Beginning finished goods units | C12: =0.2*C13 -> 1800 | D12: =C10 -> 2000 | E12: =D10 -> 2280 | F12: =E10 -> 3140 | G12: =F10 -> 4560 | H12: =G10 -> 5160 | I12: =H10 -> 6060 | J12: =I10 -> 7080 | K12: =J10 -> 5220 | ... R12: =Q10 -> 3000 | S12: =E12 -> 2280
B13: Required production units (given) | C13: 9000 | D13: 10000 | E13: 11400 | F13: 15700 | G13: 22800 | H13: 25800 | I13: 30300 | J13: 35400 | K13: 26100 | L13: 25400 | M13: 35000 | N13: 15000 | O13: 10100 | P13: 10200 | Q13: 12000 | R13: 15000 | S13: =S11-S12 -> 263200
C15: Direct Materials Budget - Alloy Steel
C16: 45985 | D16: 46015 | E16: 45682 | F16: 45713 | G16: 45741 | H16: 45772 | I16: 45802 | J16: 45833 | K16: 45863 | L16: 45894 | M16: 45925 | N16: 45955 | O16: 45986 | P16: 46016 | Q16: Jan | R16: Feb
B17: Required Production in units | C17: =C13 -> 9000 | D17: =D13 -> 10000 | E17: =E13 -> 11400 | F17: =F13 -> 15700 | G17: =G13 -> 22800 | H17: =H13 -> 25800 | I17: =I13 -> 30300 | J17: =J13 -> 35400 | ... R17: =R13 -> 15000 | S17: =SUM(E17:P17) -> 263200
B18: Direct Matreial per unit (0.5 s/m) | C18: 0.5 | D18: 0.5 | E18: 0.5 | F18: 0.5 | G18: 0.5 | H18: 0.5 | I18: 0.5 | J18: 0.5 | K18: 0.5 | L18: 0.5 | M18: 0.5 | N18: 0.5 | O18: 0.5 | P18: 0.5 | Q18: 0.5 | R18: 0.5 | S18: 0.5
B19: Total req. for production | C19: =C17*C18 -> 4500 | D19: =D17*D18 -> 5000 | E19: =E17*E18 -> 5700 | F19: =F17*F18 -> 7850 | G19: =G17*G18 -> 11400 | H19: =H17*H18 -> 12900 | I19: =I17*I18 -> 15150 | J19: =J17*J18 -> 17700 | ... S19: =S17*S18 -> 131600
B20: End inventory | C20: =21%*D19 -> 1050 | D20: =21%*E19 -> 1197 | E20: =21%*F19 -> 1648.5 | F20: =21%*G19 -> 2394 | G20: =21%*H19 -> 2709 | H20: =21%*I19 -> 3181.5 | I20: =21%*J19 -> 3717 | J20: =21%*K19 -> 2740.5 | ... Q20: =21%*R19 -> 1575 | S20: =P20 -> 1260
B21: Total required | C21: =C19+C20 -> 5550 | D21: =D19+D20 -> 6197 | E21: =E19+E20 -> 7348.5 | F21: =F19+F20 -> 10244 | G21: =G19+G20 -> 14109 | H21: =H19+H20 -> 16081.5 | I21: =I19+I20 -> 18867 | J21: =J19+J20 -> 20440.5 | ... S21: =S19+S20 -> 132860
B22: Beginning inventory | D22: =C20 -> 1050 | E22: =D20 -> 1197 | F22: =E20 -> 1648.5 | G22: =F20 -> 2394 | H22: =G20 -> 2709 | I22: =H20 -> 3181.5 | J22: =I20 -> 3717 | K22: =J20 -> 2740.5 | ... R22: =Q20 -> 1575 | S22: =E22 -> 1197
B23: DM purchases | D23: =D21-D22 -> 5147 | E23: =E21-E22 -> 6151.5 | F23: =F21-F22 -> 8595.5 | G23: =G21-G22 -> 11715 | H23: =H21-H22 -> 13372.5 | I23: =I21-I22 -> 15685.5 | J23: =J21-J22 -> 16723.5 | K23: =K21-K22 -> 12976.5 | ... Q23: =Q21-Q22 -> 6315 | S23: =S21-S22 -> 131663
B24: Cost per DM unit ($) | C24: 46 | D24: 46 | E24: 46 | F24: 46 | G24: 46 | H24: 46 | I24: 46 | J24: 46 | K24: 46 | L24: 46 | M24: 46 | N24: 46 | O24: 46 | P24: 46 | Q24: 46 | S24: 46
B25: Total cost of purchases ($) | D25: =D24*D23 -> 236762 | E25: =E24*E23 -> 282969 | F25: =F24*F23 -> 395393 | G25: =G24*G23 -> 538890 | H25: =H24*H23 -> 615135 | I25: =I24*I23 -> 721533 | J25: =J24*J23 -> 769281 | K25: =K24*K23 -> 596919 | ... Q25: =Q24*Q23 -> 290490 | S25: =S23*S24 -> 6056498
C27: Direct Materials Budget - Plastic
C28: 45985 | D28: 46015 | E28: 45682 | F28: 45713 | G28: 45741 | H28: 45772 | I28: 45802 | J28: 45833 | K28: 45863 | L28: 45894 | M28: 45925 | N28: 45955 | O28: 45986 | P28: 46016 | Q28: Jan | R28: Feb
B29: Required Production in units | C29: =C13 -> 9000 | D29: =D13 -> 10000 | E29: =E13 -> 11400 | F29: =F13 -> 15700 | G29: =G13 -> 22800 | H29: =H13 -> 25800 | I29: =I13 -> 30300 | J29: =J13 -> 35400 | ... R29: =R13 -> 15000 | S29: =SUM(E29:P29) -> 263200
B30: Direct Matreial per unit (kg) | C30: 2 | D30: 2 | E30: 2 | F30: 2 | G30: 2 | H30: 2 | I30: 2 | J30: 2 | K30: 2 | L30: 2 | M30: 2 | N30: 2 | O30: 2 | P30: 2 | Q30: 2 | R30: 2 | S30: 2
B31: Total req. for production | C31: =C29*C30 -> 18000 | D31: =D29*D30 -> 20000 | E31: =E29*E30 -> 22800 | F31: =F29*F30 -> 31400 | G31: =G29*G30 -> 45600 | H31: =H29*H30 -> 51600 | I31: =I29*I30 -> 60600 | J31: =J29*J30 -> 70800 | ... S31: =S29*S30 -> 526400
B32: End inventory | C32: =21%*D31 -> 4200 | D32: =21%*E31 -> 4788 | E32: =21%*F31 -> 6594 | F32: =21%*G31 -> 9576 | G32: =21%*H31 -> 10836 | H32: =21%*I31 -> 12726 | I32: =21%*J31 -> 14868 | J32: =21%*K31 -> 10962 | ... Q32: =21%*R31 -> 6300 | S32: =P32 -> 5040
B33: Total required | C33: =C31+C32 -> 22200 | D33: =D31+D32 -> 24788 | E33: =E31+E32 -> 29394 | F33: =F31+F32 -> 40976 | G33: =G31+G32 -> 56436 | H33: =H31+H32 -> 64326 | I33: =I31+I32 -> 75468 | J33: =J31+J32 -> 81762 | ... S33: =S31+S32 -> 531440
B34: Beginning inventory | D34: =C32 -> 4200 | E34: =D32 -> 4788 | F34: =E32 -> 6594 | G34: =F32 -> 9576 | H34: =G32 -> 10836 | I34: =H32 -> 12726 | J34: =I32 -> 14868 | K34: =J32 -> 10962 | ... R34: =Q32 -> 6300 | S34: =E34 -> 4788
B35: DM purchases | D35: =D33-D34 -> 20588 | E35: =E33-E34 -> 24606 | F35: =F33-F34 -> 34382 | G35: =G33-G34 -> 46860 | H35: =H33-H34 -> 53490 | I35: =I33-I34 -> 62742 | J35: =J33-J34 -> 66894 | K35: =K33-K34 -> 51906 | ... Q35: =Q33-Q34 -> 25260 | S35: =S33-S34 -> 526652
B36: Cost per DM unit ($) | C36: 1.2 | D36: 1.2 | E36: 1.2 | F36: 1.2 | G36: 1.2 | H36: 1.2 | I36: 1.2 | J36: 1.2 | K36: 1.2 | L36: 1.2 | M36: 1.2 | N36: 1.2 | O36: 1.2 | P36: 1.2 | Q36: 1.2 | S36: 1.2
B37: Total cost of purchases ($) | D37: =D36*D35 -> 24705.6 | E37: =E36*E35 -> 29527.2 | F37: =F36*F35 -> 41258.4 | G37: =G36*G35 -> 56232 | H37: =H36*H35 -> 64188 | I37: =I36*I35 -> 75290.4 | J37: =J36*J35 -> 80272.8 | K37: =K36*K35 -> 62287.2 | ... Q37: =Q36*Q35 -> 30312 | S37: =S35*S36 -> 631982.4
C39: Direct Materials Budget - Assembly Kits
C40: 45985 | D40: 46015 | E40: 45682 | F40: 45713 | G40: 45741 | H40: 45772 | I40: 45802 | J40: 45833 | K40: 45863 | L40: 45894 | M40: 45925 | N40: 45955 | O40: 45986 | P40: 46016 | Q40: Jan | R40: Feb
B41: Required Production in units | C41: =C13 -> 9000 | D41: =D13 -> 10000 | E41: =E13 -> 11400 | F41: =F13 -> 15700 | G41: =G13 -> 22800 | H41: =H13 -> 25800 | I41: =I13 -> 30300 | J41: =J13 -> 35400 | ... R41: =R13 -> 15000 | S41: =SUM(E41:P41) -> 263200
B42: Direct Matreial per unit (kg) | C42: 1 | D42: 1 | E42: 1 | F42: 1 | G42: 1 | H42: 1 | I42: 1 | J42: 1 | K42: 1 | L42: 1 | M42: 1 | N42: 1 | O42: 1 | P42: 1 | Q42: 1 | R42: 1 | S42: 1
B43: Total req. for production | C43: =C41*C42 -> 9000 | D43: =D41*D42 -> 10000 | E43: =E41*E42 -> 11400 | F43: =F41*F42 -> 15700 | G43: =G41*G42 -> 22800 | H43: =H41*H42 -> 25800 | I43: =I41*I42 -> 30300 | J43: =J41*J42 -> 35400 | ... S43: =S41*S42 -> 263200
...

Sheet Cash Budget
B1: Collection schedule
B2: 45985 | C2: 46015 | D2: 45682 | E2: 45713 | F2: 45741 | G2: 45772 | H2: 45802 | I2: 45833 | J2: 45863 | K2: 45894 | L2: 45925 | M2: 45955 | N2: 45986 | O2: 46016 | P2: Jan | Q2: Feb
A3: Sales | B3: ='Operating Budgets'!C87 -> 3599200 | C3: ='Operating Budgets'!D87 -> 3975480 | D3: ='Operating Budgets'!E87 -> 4310860 | E3: ='Operating Budgets'!F87 -> 5840520 | F3: ='Operating Budgets'!G87 -> 9079800 | G3: ='Operating Budgets'!H87 -> 10184100 | H3: ='Operating Budgets'!I87 -> 11975520 | I3: ='Operating Budgets'!J87 -> 15239340 | ... P3: ='Operating Budgets'!Q87 -> 4662600
A4: 45985 | B4: =30%*B3 -> 1079760 | C4: =40%*B3 -> 1439680 | D4: =30%*B3 -> 1079760
A5: 46015 | C5: =30%*C3 -> 1192644 | D5: =40%*C3 -> 1590192 | E5: =30%*C3 -> 1192644
A6: 45682 | D6: =30%*D3 -> 1293258 | E6: =D3*40% -> 1724344 | F6: =D3*30% -> 1293258
A7: 45713 | E7: =E3*30% -> 1752156 | F7: =E3*40% -> 2336208 | G7: =E3*30% -> 1752156
A8: 45741 | F8: =F3*30% -> 2723940 | G8: =F3*40% -> 3631920 | H8: =F3*30% -> 2723940
A9: 45772 | G9: =G3*30% -> 3055230 | H9: =G3*40% -> 4073640 | I9: =G3*30% -> 3055230
A10: 45802 | H10: =H3*30% -> 3592656 | I10: =H3*40% -> 4790208 | J10: =H3*30% -> 3592656
A11: 45833 | I11: =I3*30% -> 4571802 | J11: =I3*40% -> 6095736 | K11: =I3*30% -> 4571802
A12: 45863 | J12: =J3*30% -> 3219648 | K12: =J3*40% -> 4292864 | L12: =J3*30% -> 3219648
A13: 45894 | K13: =K3*30% -> 2880996 | L13: =K3*40% -> 3841328 | M13: =K3*30% -> 2880996
A14: 45925 | L14: =L3*30% -> 4212000 | M14: =L3*40% -> 5616000 | N14: =L3*30% -> 4212000
A15: 45955 | M15: =M3*30% -> 1960746 | N15: =M3*40% -> 2614328 | O15: =M3*30% -> 1960746
A16: 45986 | N16: =N3*30% -> 1236816 | O16: =N3*40% -> 1649088 | P16: =N3*30% -> 1236816
A17: 46016 | O17: =O3*30% -> 1207368 | P17: =O3*40% -> 1609824 | Q17: =O3*30% -> 1207368
A18: Total Collections | B18: =SUM(B4:B17) -> 1079760 | C18: =SUM(C4:C17) -> 2632324 | D18: =SUM(D4:D17) -> 3963210 | E18: =SUM(E4:E17) -> 4669144 | F18: =SUM(F4:F17) -> 6353406 | G18: =SUM(G4:G17) -> 8439306 | H18: =SUM(H4:H17) -> 10390236 | I18: =SUM(I4:I17) -> 12417240 | ... Q18: =SUM(Q4:Q17) -> 1207368
B20: Payment schedule
B21: 45985 | C21: 46015 | D21: 45682 | E21: 45713 | F21: 45741 | G21: 45772 | H21: 45802 | I21: 45833 | J21: 45863 | K21: 45894 | L21: 45925 | M21: 45955 | N21: 45986 | O21: 46016 | P21: Jan | Q21: Feb
A22: Total DM purchases | C22: ='Operating Budgets'!D49+'Operating Budgets'!D37+'Operating Budgets'!D25 -> 1821467.6 | D22: ='Operating Budgets'!E49+'Operating Budgets'!E37+'Operating Budgets'!E25 -> 2090896.2 | E22: ='Operating Budgets'!F49+'Operating Budgets'!F37+'Operating Budgets'!F25 -> 2885851.4 | F22: ='Operating Budgets'!G49+'Operating Budgets'!G37+'Operating Budgets'!G25 -> 4151922 | G22: ='Operating Budgets'!H49+'Operating Budgets'!H37+'Operating Budgets'!H25 -> 4704123 | H22: ='Operating Budgets'!I49+'Operating Budgets'!I37+'Operating Budgets'!I25 -> 5523623.4 | I22: ='Operating Budgets'!J49+'Operating Budgets'!J37+'Operating Budgets'!J25 -> 6371953.8 | J22: ='Operating Budgets'!K49+'Operating Budgets'!K37+'Operating Budgets'!K25 -> 4730806.2 | ... P22: ='Operating Budgets'!Q49+'Operating Budgets'!Q37+'Operating Budgets'!Q25 -> 2192802
A24: 46015 | C24: =50%*C22 -> 910733.8 | D24: =C24 -> 910733.8
A25: 45682 | D25: =50%*D22 -> 1045448.1 | E25: =D25 -> 1045448.1
A26: 45713 | E26: =50%*E22 -> 1442925.7 | F26: =E26 -> 1442925.7
A27: 45741 | F27: =50%*F22 -> 2075961 | G27: =F27 -> 2075961
A28: 45772 | G28: =50%*G22 -> 2352061.5 | H28: =G28 -> 2352061.5
A29: 45802 | H29: =50%*H22 -> 2761811.7 | I29: =H29 -> 2761811.7
A30: 45833 | I30: =50%*I22 -> 3185976.9 | J30: =I30 -> 3185976.9
A31: 45863 | J31: =50%*J22 -> 2365403.1 | K31: =J31 -> 2365403.1
A32: 45894 | K32: =50%*K22 -> 2329383.2 | L32: =K32 -> 2329383.2
A33: 45925 | L33: =50%*L22 -> 3121160 | M33: =L33 -> 3121160
A34: 45955 | M34: =50%*M22 -> 1347431.7 | N34: =M34 -> 1347431.7
A35: 45986 | N35: =50%*N22 -> 916336.7 | O35: =N35 -> 916336.7
A36: 46016 | O36: =O22*50% -> 929940.6 | P36: =O36 -> 929940.6
A37: Total payments | C37: =SUM(C24:C36) -> 910733.8 | D37: =SUM(D24:D36) -> 1956181.9 | E37: =SUM(E24:E36) -> 2488373.8 | F37: =SUM(F24:F36) -> 3518886.7 | G37: =SUM(G24:G36) -> 4428022.5 | H37: =SUM(H24:H36) -> 5113873.2 | I37: =SUM(I24:I36) -> 5947788.6 | J37: =SUM(J24:J36) -> 5551380 | ... P37: =SUM(P24:P36) -> 929940.6
B39: Cash budget
B40: 45985 | C40: 46015 | D40: 45682 | E40: 45713 | F40: 45741 | G40: 45772 | H40: 45802 | I40: 45833 | J40: 45863 | K40: 45894 | L40: 45925 | M40: 45955 | N40: 45986 | O40: 46016 | P40: Total
A41: B. cash balance | D41: 95000 | E41: =D58 -> 1212668 | F41: =E58 -> 2198562.2 | G41: =F58 -> 3298385.2 | H41: =G58 -> 5359983.4 | I41: =H58 -> 8357488.2 | J41: =I58 -> 12113885 | K41: =J58 -> 17477672 | L41: =K58 -> 22629014 | ... O41: =N58 -> 35447815 | P41: =D41 -> 95000
A42: Cash receipts
A43: Collections | D43: =D18 -> 3963210 | E43: =E18 -> 4669144 | F43: =F18 -> 6353406 | G43: =G18 -> 8439306 | H43: =H18 -> 10390236 | I43: =I18 -> 12417240 | J43: =J18 -> 12908040 | K43: =K18 -> 11745662 | ... O43: =O18 -> 4817202 | P43: =SUM(D43:O43) -> 105497308
...

Sheet Balance Sheet
A1: Escooter Inc.
A2: Balance Sheet
A3: As at Dec, 2025
A4: Assets
A5: Cash | E5: ='Cash Budget'!P58 -> 37585673
A6: Accounts Receivable | E6: =SUM('Cash Budget'!P16,'Cash Budget'!P17,'Cash Budget'!Q17) -> 4054008
A7: Raw materials inventory
A8: Alloy steel | D8: ='Operating Budgets'!S20*'Operating Budgets'!S24 -> 57960
A9: Plastic | D9: ='Operating Budgets'!S32*'Operating Budgets'!S36 -> 6048
A10: Assembly kits | D10: ='Operating Budgets'!S44*'Operating Budgets'!S48 -> 238836 | E10: =SUM(D8:D10) -> 302844
A11: Finished good inventory | E11: ='Operating Budgets'!S10*'Operating Budgets'!G111 -> 567568.92
A12: Property, plant and equipment | E12: =420000-I12 -> 367404 | H12: Depreciation | I12: ='Operating Budgets'!S78+'Operating Budgets'!S96 -> 52596 | K12: Alloy steel | L12: ='Operating Budgets'!E22*'Operating Budgets'!E24 -> 55062
A13: Total assets | E13: =SUM(E5:E12) -> 42877498 | K13: Plastic | L13: ='Operating Budgets'!E34*'Operating Budgets'!E36 -> 5745.6
K14: Assembly kits | L14: ='Operating Budgets'!E46*'Operating Budgets'!E48 -> 238836
A15: Liabilities and Shareholders equity
A16: Accounts payable | E16: ='Cash Budget'!P36 -> 929940.6
A17: Long term note | E17: =200000+'Cash Budget'!O55 -> 178000
A18: Common shares | E18: 600000
A19: Retained earnings | E19: =I30 -> 41169557 | H19: Beg cash balance | I19: 95000
A20: Total liabilities and SE | E20: =SUM(E16:E19) -> 42877498 | H20: beg A.R | I20: ='Cash Budget'!D4+'Cash Budget'!D5+'Cash Budget'!E5 -> 3862596
H21: beg F.G | I21: ='Operating Budgets'!E12*'Operating Budgets'!G111 -> 539190.48
H22: beg raw materials | I22: =SUM(L12:L14) -> 299643.6
H23: PPE | I23: 420000
H24: beg A/P | I24: =-'Cash Budget'!D24 -> -910733.8
H25: beg LT liab | I25: -200000
H26: beg common shares | I26: -600000
G27: = | H27: beg R.E | I27: =SUM(I19:I26) -> 3505696.3
H28: net income | I28: ='Operating Budgets'!G126 -> 37783861
H29: dividends | I29: =-'Cash Budget'!P50 -> -120000
H30: Ending R.E | I30: =SUM(I27:I29) -> 41169557
H33: ='Operating Budgets'!S82/'Operating Budgets'!S55 -> 4.5335258 | I33: Q.24
